Workbook
Name d: #REF!
Name d: #REF!
Name d: #REF!
Name s: '[1]SLIP-STAFF'!#REF!

Sheet DIREKSI
A1: PT. INDOBOX UTAMA JAYA
A2: DAFTAR GAJI DIREKTUR
A3: PERIODE 01 NOVEMBER S/D 30 NOVEMBER 2025
A6: NO | B6: NAMA | C6: BAGIAN | D6: STS | E6: NIK | F6: GAJI | G6: BPJS DITANGGUNG PERUSAHAAN | K6: BPJS PER- USAHAAN | L6: TOTAL GAJI | N6: TOTAL GAJI SETELAH BPJS DAN PAJAK
G7: JKK JKM | H7: JHT | I7: JP | J7: BPJS KES | M7: PPh 21
G8: 0.0119 | H8: 0.057 | I8: 0.02 | J8: 0.05
A10: 1 | B10: LEE CHUL HUN | C10: PRESIDEN DIREKTUR | D10: K2 | E10: 0077679652012000 | F10: =270000000-5045000 -> 264955000 | G10: 595000 | H10: 2850000 | I10: 1000000 | J10: 600000 | K10: =SUM(G10:J10) -> 5045000 | L10: =+F10+K10 -> 270000000 | M10: 75600000 | N10: =+F10-M10 -> 189355000
A12: SUB TOTAL | F12: =SUM(F10:F11) -> 264955000 | G12: =SUM(G10:G11) -> 595000 | H12: =SUM(H10:H11) -> 2850000 | I12: =SUM(I10:I11) -> 1000000 | J12: =SUM(J10:J11) -> 600000 | K12: =SUM(K10:K11) -> 5045000 | L12: =SUM(L10:L11) -> 270000000 | M12: =SUM(M10:M11) -> 75600000 | N12: =SUM(N10:N11) -> 189355000

Sheet STAFF
A1: PT INDOBOX UTAMA JAYA
A2: DAFTAR GAJI STAFF
A3: PERIODE 01 NOVEMBER S/D 30 NOVEMBER 2025
A5: NO | B5: NAMA | C5: MASA | D5: JABATAN | E5: STS | F5: NIK | G5: GAJI POKOK | H5: LEMBUR | I5: TUNJANGAN | N5: TOTAL GAJI | O5: BPJS DITANGGUNG PERUSAHAAN | S5: BPJS PER- USAHAAN | T5: GAJI BRUTO | U5: BPJS DITANGGUNG KARYAWAN | Y5: POTONGAN | AA5: Gaji Setelah PPh 21 | AD5: BPJS TK | AE5: JKN | AF5: GAJI BRUTO | AG5: BIAYA JABATAN | AH5: GAJI NETTO | AI5: GAJI SETAHUN | AJ5: PTKP | AK5: PKP | AL5: PPH 21 SETAHUN | AM5: PPH 21 SEBULAN
C6: KERJA | I6: UANG JABATAN | J6: PRESTASI / | K6: BONUS | L6: UANG | M6: THR/ | O6: JKK JKM | P6: JHT | Q6: JP | R6: BPJS KES | U6: JHT | V6: JP | W6: BPJS KES | X6: TAMBAHAN | Y6: BPJS | Z6: PPh 21
L7: MAKAN | M7: BONUS | O7: 0.0119 | P7: 0.02 | Q7: 0.02 | R7: 0.04 | U7: 0.02 | V7: 0.01 | W7: 0.01 | X7: 0.01 | Y7: TK + KES | AA7: (THP) | AG7: 0.05 | AI7: 12
A9: 1 | B9: EDDY SILALAHI, SE | C9: 12 | D9: CHIEF ACC. | E9: K1 | F9: 3603280210600004 | G9: 8500000 | I9: 0 | J9: 0 | K9: 0 | L9: 0 | N9: =SUM(G9:M9) -> 8500000 | O9: 0 | P9: 0 | Q9: 0 | R9: =+AE9*$R$7 -> 340000 | S9: =SUM(O9:R9) -> 340000 | T9: =+N9+S9 -> 8840000 | U9: 0 | V9: 0 | W9: =+AE9*$W$7 -> 85000 | X9: 0 | Y9: =SUM(U9:X9) -> 85000 | Z9: 88400 | AA9: =+N9-Y9-Z9 -> 8326600 | AB9: + | AD9: 0 | AE9: =+N9 -> 8500000 | AF9: =+N9+O9+R9 -> 8840000 | AG9: =IF(AF9*$AG$7>500000,500000,AF9*$AG$7) -> 442000 | AH9: =+AF9-AG9-U9-V9 -> 8398000 | AI9: =+AH9*$AI$7 -> 100776000 | AJ9: =IF(E9="TK",54000000,(IF(OR(E9="TK1",E9="K"),58500000,(IF(OR(E9="TK2",E9="K1"),63000000,(IF(OR(OR(E9="TK3",E9="TK4"),E9="K2"),67500000,72000000))))))) -> 63000000 | AK9: =IF((+AI9-AJ9)<=0,0,TRUNC((AI9-AJ9)/1000)*1000) -> 37776000 | AL9: =IF(AK9<=60000000,AK9*5%,IF(AK9<=250000000,3000000+((AK9-60000000)*15%),IF(AK9<=500000000,31500000+((AK9-250000000)*25%),IF(AND(AK9>=500000000,AK9<=5000000000),94000000+((AK9-500000000)*30%),IF(AK9>5000000000,(1444000000+(AK9-5000000000)*35%)))))) -> 1888800 | AM9: =+AL9/12 -> 157400
A10: 2 | B10: KUSUMA DWI P. | C10: 12 | D10: MARKETING | E10: TK | F10: 3201275203830011 | G10: 9450558 | I10: 500000 | J10: 0 | K10: 0 | L10: 0 | N10: =SUM(G10:M10) -> 9950558 | O10: =+AD10*$O$7 -> 112461.64 | P10: =+AD10*$P$7 -> 189011.16 | Q10: =+AD10*$Q$7 -> 189011.16 | R10: =+AE10*$R$7 -> 398022.32 | S10: =SUM(O10:R10) -> 888506.28 | T10: =+N10+S10 -> 10839064 | U10: =+AD10*$U$7 -> 189011.16 | V10: =+AD10*$V$7 -> 94505.58 | W10: =+AE10*$W$7 -> 99505.58 | X10: 0 | Y10: =SUM(U10:X10) -> 383022.32 | Z10: 261526 | AA10: =+N10-Y10-Z10 -> 9306009.7 | AD10: =+G10 -> 9450558 | AE10: =+N10 -> 9950558 | AF10: =+N10+O10+R10 -> 10461042 | AG10: =IF(AF10*$AG$7>500000,500000,AF10*$AG$7) -> 500000 | AH10: =+AF10-AG10-U10-V10 -> 9677525.2 | AI10: =+AH10*$AI$7 -> 1.161303e+08 | AJ10: =IF(E10="TK",54000000,(IF(OR(E10="TK1",E10="K"),58500000,(IF(OR(E10="TK2",E10="K1"),63000000,(IF(OR(OR(E10="TK3",E10="TK4"),E10="K2"),67500000,72000000))))))) -> 54000000 | AK10: =IF((+AI10-AJ10)<=0,0,TRUNC((AI10-AJ10)/1000)*1000) -> 62130000 | AL10: =IF(AK10<=60000000,AK10*5%,IF(AK10<=250000000,3000000+((AK10-60000000)*15%),IF(AK10<=500000000,31500000+((AK10-250000000)*25%),IF(AND(AK10>=500000000,AK10<=5000000000),94000000+((AK10-500000000)*30%),IF(AK10>5000000000,(1444000000+(AK10-5000000000)*35%)))))) -> 3319500 | AM10: =+AL10/12 -> 276625
A11: 3 | B11: ERNI NURAENI | C11: 12 | D11: MARKETING | E11: TK | F11: 3201026310890011 | G11: 7845749 | I11: 300000 | J11: 0 | K11: 0 | L11: 0 | N11: =SUM(G11:M11) -> 8145749 | O11: =+AD11*$O$7 -> 93364.413 | P11: =+AD11*$P$7 -> 156914.98 | Q11: =+AD11*$Q$7 -> 156914.98 | R11: =+AE11*$R$7 -> 325829.96 | S11: =SUM(O11:R11) -> 733024.33 | T11: =+N11+S11 -> 8878773.3 | U11: =+AD11*$U$7 -> 156914.98 | V11: =+AD11*$V$7 -> 78457.49 | W11: =+AE11*$W$7 -> 81457.49 | X11: =+W11*1 -> 81457.49 | Y11: =SUM(U11:X11) -> 398287.45 | Z11: 149887 | AA11: =+N11-Y11-Z11 -> 7597574.5 | AD11: =+G11 -> 7845749 | AE11: =+N11 -> 8145749 | AF11: =+N11+O11+R11 -> 8564943.4 | AG11: =IF(AF11*$AG$7>500000,500000,AF11*$AG$7) -> 428247.17 | AH11: =+AF11-AG11-U11-V11 -> 7901323.7 | AI11: =+AH11*$AI$7 -> 94815885 | AJ11: =IF(E11="TK",54000000,(IF(OR(E11="TK1",E11="K"),58500000,(IF(OR(E11="TK2",E11="K1"),63000000,(IF(OR(OR(E11="TK3",E11="TK4"),E11="K2"),67500000,72000000))))))) -> 54000000 | AK11: =IF((+AI11-AJ11)<=0,0,TRUNC((AI11-AJ11)/1000)*1000) -> 40815000 | AL11: =IF(AK11<=60000000,AK11*5%,IF(AK11<=250000000,3000000+((AK11-60000000)*15%),IF(AK11<=500000000,31500000+((AK11-250000000)*25%),IF(AND(AK11>=500000000,AK11<=5000000000),94000000+((AK11-500000000)*30%),IF(AK11>5000000000,(1444000000+(AK11-5000000000)*35%)))))) -> 2040750 | AM11: =+AL11/12 -> 170062.5
A12: 4 | B12: SRI WAHYUNI | C12: 12 | D12: PERSONALIA | E12: TK | F12: 3201026406760009 | G12: 10106032 | I12: 700000 | J12: 0 | K12: 0 | L12: 0 | N12: =SUM(G12:M12) -> 10806032 | O12: =+AD12*$O$7 -> 120261.78 | P12: =+AD12*$P$7 -> 202120.64 | Q12: =+AD12*$Q$7 -> 202120.64 | R12: =+AE12*$R$7 -> 432241.28 | S12: =SUM(O12:R12) -> 956744.34 | T12: =+N12+S12 -> 11762776 | U12: =+AD12*$U$7-95931 -> 106189.64 | V12: =+AD12*$V$7 -> 101060.32 | W12: =+AE12*$W$7 -> 108060.32 | X12: =+W12*1 -> 108060.32 | Y12: =SUM(U12:X12) -> 423370.6 | Z12: 397549 | AA12: =+N12-Y12-Z12 -> 9985112.4 | AD12: =+G12 -> 10106032 | AE12: =+N12 -> 10806032 | AF12: =+N12+O12+R12 -> 11358535 | AG12: =IF(AF12*$AG$7>500000,500000,AF12*$AG$7) -> 500000 | AH12: =+AF12-AG12-U12-V12 -> 10651285 | AI12: =+AH12*$AI$7 -> 1.2781542e+08 | AJ12: =IF(E12="TK",54000000,(IF(OR(E12="TK1",E12="K"),58500000,(IF(OR(E12="TK2",E12="K1"),63000000,(IF(OR(OR(E12="TK3",E12="TK4"),E12="K2"),67500000,72000000))))))) -> 54000000 | AK12: =IF((+AI12-AJ12)<=0,0,TRUNC((AI12-AJ12)/1000)*1000) -> 73815000 | AL12: =IF(AK12<=60000000,AK12*5%,IF(AK12<=250000000,3000000+((AK12-60000000)*15%),IF(AK12<=500000000,31500000+((AK12-250000000)*25%),IF(AND(AK12>=500000000,AK12<=5000000000),94000000+((AK12-500000000)*30%),IF(AK12>5000000000,(1444000000+(AK12-5000000000)*35%)))))) -> 5072250 | AM12: =+AL12/12 -> 422687.5
A13: 5 | B13: TUTI NUR PRATIWI | C13: 12 | D13: FINANCE | E13: K2 | F13: 3201024708880005 | G13: 7970090 | I13: 500000 | J13: 0 | K13: 0 | L13: 0 | N13: =SUM(G13:M13) -> 8470090 | O13: =+AD13*$O$7 -> 94844.071 | P13: =+AD13*$P$7 -> 159401.8 | Q13: =+AD13*$Q$7 -> 159401.8 | R13: =+AE13*$R$7 -> 338803.6 | S13: =SUM(O13:R13) -> 752451.27 | T13: =+N13+S13 -> 9222541.3 | U13: =+AD13*$U$7 -> 159401.8 | V13: =+AD13*$V$7 -> 79700.9 | W13: =+AE13*$W$7 -> 84700.9 | X13: =+W13*2+2920+15 -> 172336.8 | Y13: =SUM(U13:X13) -> 496140.4 | Z13: 89037 | AA13: =+N13-Y13-Z13 -> 7884912.6 | AD13: =+G13 -> 7970090 | AE13: =+N13 -> 8470090 | AF13: =+N13+O13+R13 -> 8903737.7 | AG13: =IF(AF13*$AG$7>500000,500000,AF13*$AG$7) -> 445186.88 | AH13: =+AF13-AG13-U13-V13 -> 8219448.1 | AI13: =+AH13*$AI$7 -> 98633377 | AJ13: =IF(E13="TK",54000000,(IF(OR(E13="TK1",E13="K"),58500000,(IF(OR(E13="TK2",E13="K1"),63000000,(IF(OR(OR(E13="TK3",E13="TK4"),E13="K2"),67500000,72000000))))))) -> 67500000 | AK13: =IF((+AI13-AJ13)<=0,0,TRUNC((AI13-AJ13)/1000)*1000) -> 31133000 | AL13: =IF(AK13<=60000000,AK13*5%,IF(AK13<=250000000,3000000+((AK13-60000000)*15%),IF(AK13<=500000000,31500000+((AK13-250000000)*25%),IF(AND(AK13>=500000000,AK13<=5000000000),94000000+((AK13-500000000)*30%),IF(AK13>5000000000,(1444000000+(AK13-5000000000)*35%)))))) -> 1556650 | AM13: =+AL13/12 -> 129720.83
A14: 6 | B14: UJANG SAILAN | C14: 12 | D14: KPL.WONDAN | E14: K1 | F14: 3201022705750006 | G14: 8321247 | I14: 300000 | J14: 0 | K14: 0 | L14: 0 | N14: =SUM(G14:M14) -> 8621247 | O14: =+AD14*$O$7 -> 99022.839 | P14: =+AD14*$P$7 -> 166424.94 | Q14: =+AD14*$Q$7 -> 166424.94 | R14: =+AE14*$R$7 -> 344849.88 | S14: =SUM(O14:R14) -> 776722.6 | T14: =+N14+S14 -> 9397969.6 | U14: =+AD14*$U$7 -> 166424.94 | V14: =+AD14*$V$7 -> 83212.47 | W14: =+AE14*$W$7 -> 86212.47 | X14: =+W14*1 -> 86212.47 | Y14: =SUM(U14:X14) -> 422062.35 | Z14: 90651 | AA14: =+N14-Y14-Z14 -> 8108533.7 | AD14: =+G14 -> 8321247 | AE14: =+N14 -> 8621247 | AF14: =+N14+O14+R14 -> 9065119.7 | AG14: =IF(AF14*$AG$7>500000,500000,AF14*$AG$7) -> 453255.99 | AH14: =+AF14-AG14-U14-V14 -> 8362226.3 | AI14: =+AH14*$AI$7 -> 1.0034672e+08 | AJ14: =IF(E14="TK",54000000,(IF(OR(E14="TK1",E14="K"),58500000,(IF(OR(E14="TK2",E14="K1"),63000000,(IF(OR(OR(E14="TK3",E14="TK4"),E14="K2"),67500000,72000000))))))) -> 63000000 | AK14: =IF((+AI14-AJ14)<=0,0,TRUNC((AI14-AJ14)/1000)*1000) -> 37346000 | AL14: =IF(AK14<=60000000,AK14*5%,IF(AK14<=250000000,3000000+((AK14-60000000)*15%),IF(AK14<=500000000,31500000+((AK14-250000000)*25%),IF(AND(AK14>=500000000,AK14<=5000000000),94000000+((AK14-500000000)*30%),IF(AK14>5000000000,(1444000000+(AK14-5000000000)*35%)))))) -> 1867300 | AM14: =+AL14/12 -> 155608.33
A15: 7 | B15: INDRA WIJAYA KUSUMA | C15: 12 | D15: KPL.SHIFT | E15: K2 | F15: 3201021111850018 | G15: 8700359 | I15: 500000 | J15: 0 | K15: 0 | L15: 0 | N15: =SUM(G15:M15) -> 9200359 | O15: =+AD15*$O$7 -> 103534.27 | P15: =+AD15*$P$7 -> 174007.18 | Q15: =+AD15*$Q$7 -> 174007.18 | R15: =+AE15*$R$7 -> 368014.36 | S15: =SUM(O15:R15) -> 819562.99 | T15: =+N15+S15 -> 10019922 | U15: =+AD15*$U$7 -> 174007.18 | V15: =+AD15*$V$7 -> 87003.59 | W15: =+AE15*$W$7 -> 92003.59 | X15: 0 | Y15: =SUM(U15:X15) -> 353014.36 | Z15: 145079 | AA15: =+N15-Y15-Z15 -> 8702265.6 | AD15: =+G15 -> 8700359 | AE15: =+N15 -> 9200359 | AF15: =+N15+O15+R15 -> 9671907.6 | AG15: =IF(AF15*$AG$7>500000,500000,AF15*$AG$7) -> 483595.38 | AH15: =+AF15-AG15-U15-V15 -> 8927301.5 | AI15: =+AH15*$AI$7 -> 1.0712762e+08 | AJ15: =IF(E15="TK",54000000,(IF(OR(E15="TK1",E15="K"),58500000,(IF(OR(E15="TK2",E15="K1"),63000000,(IF(OR(OR(E15="TK3",E15="TK4"),E15="K2"),67500000,72000000))))))) -> 67500000 | AK15: =IF((+AI15-AJ15)<=0,0,TRUNC((AI15-AJ15)/1000)*1000) -> 39627000 | AL15: =IF(AK15<=60000000,AK15*5%,IF(AK15<=250000000,3000000+((AK15-60000000)*15%),IF(AK15<=500000000,31500000+((AK15-250000000)*25%),IF(AND(AK15>=500000000,AK15<=5000000000),94000000+((AK15-500000000)*30%),IF(AK15>5000000000,(1444000000+(AK15-5000000000)*35%)))))) -> 1981350 | AM15: =+AL15/12 -> 165112.5
A16: 8 | B16: SANAN BIN AJA | C16: 12 | D16: KPL.SHIFT | E16: K1 | F16: 3201072609800003 | G16: 8700359 | I16: 500000 | J16: 0 | K16: 0 | L16: 0 | N16: =SUM(G16:M16) -> 9200359 | O16: =+AD16*$O$7 -> 103534.27 | P16: =+AD16*$P$7 -> 174007.18 | Q16: =+AD16*$Q$7 -> 174007.18 | R16: =+AE16*$R$7 -> 368014.36 | S16: =SUM(O16:R16) -> 819562.99 | T16: =+N16+S16 -> 10019922 | U16: =+AD16*$U$7 -> 174007.18 | V16: =+AD16*$V$7 -> 87003.59 | W16: =+AE16*$W$7 -> 92003.59 | X16: 0 | Y16: =SUM(U16:X16) -> 353014.36 | Z16: 145079 | AA16: =+N16-Y16-Z16 -> 8702265.6 | AD16: =+G16 -> 8700359 | AE16: =+N16 -> 9200359 | AF16: =+N16+O16+R16 -> 9671907.6 | AG16: =IF(AF16*$AG$7>500000,500000,AF16*$AG$7) -> 483595.38 | AH16: =+AF16-AG16-U16-V16 -> 8927301.5 | AI16: =+AH16*$AI$7 -> 1.0712762e+08 | AJ16: =IF(E16="TK",54000000,(IF(OR(E16="TK1",E16="K"),58500000,(IF(OR(E16="TK2",E16="K1"),63000000,(IF(OR(OR(E16="TK3",E16="TK4"),E16="K2"),67500000,72000000))))))) -> 63000000 | AK16: =IF((+AI16-AJ16)<=0,0,TRUNC((AI16-AJ16)/1000)*1000) -> 44127000 | AL16: =IF(AK16<=60000000,AK16*5%,IF(AK16<=250000000,3000000+((AK16-60000000)*15%),IF(AK16<=500000000,31500000+((AK16-250000000)*25%),IF(AND(AK16>=500000000,AK16<=5000000000),94000000+((AK16-500000000)*30%),IF(AK16>5000000000,(1444000000+(AK16-5000000000)*35%)))))) -> 2206350 | AM16: =+AL16/12 -> 183862.5
A17: 9 | B17: ABDUROHMAT YUSUP | C17: 12 | D17: KPL.DELIVERY | E17: K2 | F17: 3201021309850004 | G17: 6519752 | I17: 300000 | J17: 0 | K17: 0 | L17: 0 | N17: =SUM(G17:M17) -> 6819752 | O17: =+AD17*$O$7 -> 77585.049 | P17: =+AD17*$P$7 -> 130395.04 | Q17: =+AD17*$Q$7 -> 130395.04 | R17: =+AE17*$R$7 -> 272790.08 | S17: =SUM(O17:R17) -> 611165.21 | T17: =+N17+S17 -> 7430917.2 | U17: =+AD17*$U$7 -> 130395.04 | V17: =+AD17*$V$7 -> 65197.52 | W17: =+AE17*$W$7 -> 68197.52 | X17: 0 | Y17: =SUM(U17:X17) -> 263790.08 | Z17: 53776 | AA17: =+N17-Y17-Z17 -> 6502185.9 | AD17: =+G17 -> 6519752 | AE17: =+N17 -> 6819752 | AF17: =+N17+O17+R17 -> 7170127.1 | AG17: =IF(AF17*$AG$7>500000,500000,AF17*$AG$7) -> 358506.36 | AH17: =+AF17-AG17-U17-V17 -> 6616028.2 | AI17: =+AH17*$AI$7 -> 79392339 | AJ17: =IF(E17="TK",54000000,(IF(OR(E17="TK1",E17="K"),58500000,(IF(OR(E17="TK2",E17="K1"),63000000,(IF(OR(OR(E17="TK3",E17="TK4"),E17="K2"),67500000,72000000))))))) -> 67500000 | AK17: =IF((+AI17-AJ17)<=0,0,TRUNC((AI17-AJ17)/1000)*1000) -> 11892000 | AL17: =IF(AK17<=60000000,AK17*5%,IF(AK17<=250000000,3000000+((AK17-60000000)*15%),IF(AK17<=500000000,31500000+((AK17-250000000)*25%),IF(AND(AK17>=500000000,AK17<=5000000000),94000000+((AK17-500000000)*30%),IF(AK17>5000000000,(1444000000+(AK17-5000000000)*35%)))))) -> 594600 | AM17: =+AL17/12 -> 49550
A18: 10 | B18: MUH ARIF ROFIUDIN | C18: 12 | D18: FINISHING | E18: K1 | F18: 3201080506810002 | G18: 6009388 | I18: 200000 | J18: 0 | K18: 0 | L18: 0 | N18: =SUM(G18:M18) -> 6209388 | O18: =+AD18*$O$7 -> 71511.717 | P18: =+AD18*$P$7 -> 120187.76 | Q18: =+AD18*$Q$7 -> 120187.76 | R18: =+AE18*$R$7 -> 248375.52 | S18: =SUM(O18:R18) -> 560262.76 | T18: =+N18+S18 -> 6769650.8 | U18: =+AD18*$U$7 -> 120187.76 | V18: =+AD18*$V$7 -> 60093.88 | W18: =+AE18*$W$7 -> 62093.88 | X18: 0 | Y18: =SUM(U18:X18) -> 242375.52 | Z18: 32646 | AA18: =+N18-Y18-Z18 -> 5934366.5 | AD18: =+G18 -> 6009388 | AE18: =+N18 -> 6209388 | AF18: =+N18+O18+R18 -> 6529275.2 | AG18: =IF(AF18*$AG$7>500000,500000,AF18*$AG$7) -> 326463.76 | AH18: =+AF18-AG18-U18-V18 -> 6022529.8 | AI18: =+AH18*$AI$7 -> 72270358 | AJ18: =IF(E18="TK",54000000,(IF(OR(E18="TK1",E18="K"),58500000,(IF(OR(E18="TK2",E18="K1"),63000000,(IF(OR(OR(E18="TK3",E18="TK4"),E18="K2"),67500000,72000000))))))) -> 63000000 | AK18: =IF((+AI18-AJ18)<=0,0,TRUNC((AI18-AJ18)/1000)*1000) -> 9270000 | AL18: =IF(AK18<=60000000,AK18*5%,IF(AK18<=250000000,3000000+((AK18-60000000)*15%),IF(AK18<=500000000,31500000+((AK18-250000000)*25%),IF(AND(AK18>=500000000,AK18<=5000000000),94000000+((AK18-500000000)*30%),IF(AK18>5000000000,(1444000000+(AK18-5000000000)*35%)))))) -> 463500 | AM18: =+AL18/12 -> 38625
A19: 11 | B19: MANSUR BIN SAIRAN | C19: 12 | D19: KPL.DELIVERY | E19: K3 | F19: 3201020706810006 | G19: 6244338 | I19: 200000 | J19: 0 | K19: 0 | L19: 0 | N19: =SUM(G19:M19) -> 6444338 | O19: =+AD19*$O$7 -> 74307.622 | P19: =+AD19*$P$7 -> 124886.76 | Q19: =+AD19*$Q$7 -> 124886.76 | R19: =+AE19*$R$7 -> 257773.52 | S19: =SUM(O19:R19) -> 581854.66 | T19: =+N19+S19 -> 7026192.7 | U19: =+AD19*$U$7 -> 124886.76 | V19: =+AD19*$V$7 -> 62443.38 | W19: =+AE19*$W$7 -> 64443.38 | X19: 0 | Y19: =SUM(U19:X19) -> 251773.52 | Z19: 16941 | AA19: =+N19-Y19-Z19 -> 6175623.5 | AD19: =+G19 -> 6244338 | AE19: =+N19 -> 6444338 | AF19: =+N19+O19+R19 -> 6776419.1 | AG19: =IF(AF19*$AG$7>500000,500000,AF19*$AG$7) -> 338820.96 | AH19: =+AF19-AG19-U19-V19 -> 6250268 | AI19: =+AH19*$AI$7 -> 75003217 | AJ19: =IF(E19="TK",54000000,(IF(OR(E19="TK1",E19="K"),58500000,(IF(OR(E19="TK2",E19="K1"),63000000,(IF(OR(OR(E19="TK3",E19="TK4"),E19="K2"),67500000,72000000))))))) -> 72000000 | AK19: =IF((+AI19-AJ19)<=0,0,TRUNC((AI19-AJ19)/1000)*1000) -> 3003000 | AL19: =IF(AK19<=60000000,AK19*5%,IF(AK19<=250000000,3000000+((AK19-60000000)*15%),IF(AK19<=500000000,31500000+((AK19-250000000)*25%),IF(AND(AK19>=500000000,AK19<=5000000000),94000000+((AK19-500000000)*30%),IF(AK19>5000000000,(1444000000+(AK19-5000000000)*35%)))))) -> 150150 | AM19: =+AL19/12 -> 12512.5
A20: 12 | B20: SUMIYATI | C20: 12 | D20: PURCHASING | E20: TK | F20: 3201025401940010 | G20: 6340220 | I20: 200000 | J20: 0 | K20: 0 | L20: 0 | N20: =SUM(G20:M20) -> 6540220 | O20: =+AD20*$O$7 -> 75448.618 | P20: =+AD20*$P$7 -> 126804.4 | Q20: =+AD20*$Q$7 -> 126804.4 | R20: =+AE20*$R$7 -> 261608.8 | S20: =SUM(O20:R20) -> 590666.22 | T20: =+N20+S20 -> 7130886.2 | U20: =+AD20*$U$7 -> 126804.4 | V20: =+AD20*$V$7 -> 63402.2 | W20: =+AE20*$W$7 -> 65402.2 | X20: =+W20*2 -> 130804.4 | Y20: =SUM(U20:X20) -> 386413.2 | Z20: 85966 | AA20: =+N20-Y20-Z20 -> 6067840.8 | AD20: =+G20 -> 6340220 | AE20: =+N20 -> 6540220 | AF20: =+N20+O20+R20 -> 6877277.4 | AG20: =IF(AF20*$AG$7>500000,500000,AF20*$AG$7) -> 343863.87 | AH20: =+AF20-AG20-U20-V20 -> 6343206.9 | AI20: =+AH20*$AI$7 -> 76118483 | AJ20: =IF(E20="TK",54000000,(IF(OR(E20="TK1",E20="K"),58500000,(IF(OR(E20="TK2",E20="K1"),63000000,(IF(OR(OR(E20="TK3",E20="TK4"),E20="K2"),67500000,72000000))))))) -> 54000000 | AK20: =IF((+AI20-AJ20)<=0,0,TRUNC((AI20-AJ20)/1000)*1000) -> 22118000 | AL20: =IF(AK20<=60000000,AK20*5%,IF(AK20<=250000000,3000000+((AK20-60000000)*15%),IF(AK20<=500000000,31500000+((AK20-250000000)*25%),IF(AND(AK20>=500000000,AK20<=5000000000),94000000+((AK20-500000000)*30%),IF(AK20>5000000000,(1444000000+(AK20-5000000000)*35%)))))) -> 1105900 | AM20: =+AL20/12 -> 92158.333
A21: 13 | B21: ENCEP IMAN | C21: 12 | D21: FINISHING | E21: K2 | F21: 3201022209710009 | G21: 6046413 | I21: 300000 | J21: 0 | K21: 0 | L21: 0 | N21: =SUM(G21:M21) -> 6346413 | O21: =+AD21*$O$7 -> 71952.315 | P21: =+AD21*$P$7 -> 120928.26 | Q21: =+AD21*$Q$7 -> 120928.26 | R21: =+AE21*$R$7 -> 253856.52 | S21: =SUM(O21:R21) -> 567665.35 | T21: =+N21+S21 -> 6914078.4 | U21: =+AD21*$U$7 -> 120928.26 | V21: =+AD21*$V$7 -> 60464.13 | W21: =+AE21*$W$7 -> 63464.13 | X21: 0 | Y21: =SUM(U21:X21) -> 244856.52 | Z21: 66722 | AA21: =+N21-Y21-Z21 -> 6034834.5 | AD21: =+G21 -> 6046413 | AE21: =+N21 -> 6346413 | AF21: =+N21+O21+R21 -> 6672221.8 | AG21: =IF(AF21*$AG$7>500000,500000,AF21*$AG$7) -> 333611.09 | AH21: =+AF21-AG21-U21-V21 -> 6157218.4 | AI21: =+AH21*$AI$7 -> 73886620 | AJ21: =IF(E21="TK",54000000,(IF(OR(E21="TK1",E21="K"),58500000,(IF(OR(E21="TK2",E21="K1"),63000000,(IF(OR(OR(E21="TK3",E21="TK4"),E21="K2"),67500000,72000000))))))) -> 67500000 | AK21: =IF((+AI21-AJ21)<=0,0,TRUNC((AI21-AJ21)/1000)*1000) -> 6386000 | AL21: =IF(AK21<=60000000,AK21*5%,IF(AK21<=250000000,3000000+((AK21-60000000)*15%),IF(AK21<=500000000,31500000+((AK21-250000000)*25%),IF(AND(AK21>=500000000,AK21<=5000000000),94000000+((AK21-500000000)*30%),IF(AK21>5000000000,(1444000000+(AK21-5000000000)*35%)))))) -> 319300 | AM21: =+AL21/12 -> 26608.333
A22: 14 | B22: RINA AULIA KRESNA R | C22: 12 | D22: ACCOUNTING | E22: TK | F22: 3201026001960004 | G22: 5353160 | I22: 200000 | J22: 0 | K22: 0 | L22: 0 | N22: =SUM(G22:M22) -> 5553160 | O22: =+AD22*$O$7 -> 63702.604 | P22: =+AD22*$P$7 -> 107063.2 | Q22: =+AD22*$Q$7 -> 107063.2 | R22: =+AE22*$R$7 -> 222126.4 | S22: =SUM(O22:R22) -> 499955.4 | T22: =+N22+S22 -> 6053115.4 | U22: =+AD22*$U$7 -> 107063.2 | V22: =+AD22*$V$7 -> 53531.6 | W22: =+AE22*$W$7 -> 55531.6 | X22: 0 | Y22: =SUM(U22:X22) -> 216126.4 | Z22: 29195 | AA22: =+N22-Y22-Z22 -> 5307838.6 | AD22: =+G22 -> 5353160 | AE22: =+N22 -> 5553160 | AF22: =+N22+O22+R22 -> 5838989 | AG22: =IF(AF22*$AG$7>500000,500000,AF22*$AG$7) -> 291949.45 | AH22: =+AF22-AG22-U22-V22 -> 5386444.8 | AI22: =+AH22*$AI$7 -> 64637337 | AJ22: =IF(E22="TK",54000000,(IF(OR(E22="TK1",E22="K"),58500000,(IF(OR(E22="TK2",E22="K1"),63000000,(IF(OR(OR(E22="TK3",E22="TK4"),E22="K2"),67500000,72000000))))))) -> 54000000 | AK22: =IF((+AI22-AJ22)<=0,0,TRUNC((AI22-AJ22)/1000)*1000) -> 10637000 | AL22: =IF(AK22<=60000000,AK22*5%,IF(AK22<=250000000,3000000+((AK22-60000000)*15%),IF(AK22<=500000000,31500000+((AK22-250000000)*25%),IF(AND(AK22>=500000000,AK22<=5000000000),94000000+((AK22-500000000)*30%),IF(AK22>5000000000,(1444000000+(AK22-5000000000)*35%)))))) -> 531850 | AM22: =+AL22/12 -> 44320.833
A23: 15 | B23: LUTHFYA BILQIS | C23: 12 | D23: ADM BC | E23: TK | F23: 3317146201000001 | G23: 4877211 | I23: 200000 | J23: 0 | K23: 0 | L23: 0 | N23: =SUM(G23:M23) -> 5077211 | O23: =+AD23*$O$7 -> 58038.811 | P23: =+AD23*$P$7 -> 97544.22 | Q23: =+AD23*$Q$7 -> 97544.22 | R23: =+AE23*$R$7 -> 203088.44 | S23: =SUM(O23:R23) -> 456215.69 | T23: =+N23+S23 -> 5533426.7 | U23: =+AD23*$U$7 -> 97544.22 | V23: =+AD23*$V$7 -> 48772.11 | W23: =+AE23*$W$7 -> 50772.11 | X23: 0 | Y23: =SUM(U23:X23) -> 197088.44 | Z23: 0 | AA23: =+N23-Y23-Z23 -> 4880122.6 | AD23: =+G23 -> 4877211 | AE23: =+N23 -> 5077211 | AF23: =+N23+O23+R23 -> 5338338.3 | AG23: =IF(AF23*$AG$7>500000,500000,AF23*$AG$7) -> 266916.91 | AH23: =+AF23-AG23-U23-V23 -> 4925105 | AI23: =+AH23*$AI$7 -> 59101260 | AJ23: =IF(E23="TK",54000000,(IF(OR(E23="TK1",E23="K"),58500000,(IF(OR(E23="TK2",E23="K1"),63000000,(IF(OR(OR(E23="TK3",E23="TK4"),E23="K2"),67500000,72000000))))))) -> 54000000 | AK23: =IF((+AI23-AJ23)<=0,0,TRUNC((AI23-AJ23)/1000)*1000) -> 5101000 | AL23: =IF(AK23<=60000000,AK23*5%,IF(AK23<=250000000,3000000+((AK23-60000000)*15%),IF(AK23<=500000000,31500000+((AK23-250000000)*25%),IF(AND(AK23>=500000000,AK23<=5000000000),94000000+((AK23-500000000)*30%),IF(AK23>5000000000,(1444000000+(AK23-5000000000)*35%)))))) -> 255050 | AM23: =+AL23/12 -> 21254.167
A24: 16 | B24: IBNU NURDIANSYAH | C24: 12 | D24: ADM PRODUKSI | E24: TK | F24: 3201021605010002 | G24: 4877211 | I24: 200000 | J24: 0 | K24: 0 | L24: 0 | N24: =SUM(G24:M24) -> 5077211 | O24: =+AD24*$O$7 -> 58038.811 | P24: =+AD24*$P$7 -> 97544.22 | Q24: =+AD24*$Q$7 -> 97544.22 | R24: =+AE24*$R$7 -> 203088.44 | S24: =SUM(O24:R24) -> 456215.69 | T24: =+N24+S24 -> 5533426.7 | U24: =+AD24*$U$7 -> 97544.22 | V24: =+AD24*$V$7 -> 48772.11 | W24: =+AE24*$W$7 -> 50772.11 | X24: 0 | Y24: =SUM(U24:X24) -> 197088.44 | Z24: 0 | AA24: =+N24-Y24-Z24 -> 4880122.6 | AD24: =+G24 -> 4877211 | AE24: =+N24 -> 5077211 | AF24: =+N24+O24+R24 -> 5338338.3 | AG24: =IF(AF24*$AG$7>500000,500000,AF24*$AG$7) -> 266916.91 | AH24: =+AF24-AG24-U24-V24 -> 4925105 | AI24: =+AH24*$AI$7 -> 59101260 | AJ24: =IF(E24="TK",54000000,(IF(OR(E24="TK1",E24="K"),58500000,(IF(OR(E24="TK2",E24="K1"),63000000,(IF(OR(OR(E24="TK3",E24="TK4"),E24="K2"),67500000,72000000))))))) -> 54000000 | AK24: =IF((+AI24-AJ24)<=0,0,TRUNC((AI24-AJ24)/1000)*1000) -> 5101000 | AL24: =IF(AK24<=60000000,AK24*5%,IF(AK24<=250000000,3000000+((AK24-60000000)*15%),IF(AK24<=500000000,31500000+((AK24-250000000)*25%),IF(AND(AK24>=500000000,AK24<=5000000000),94000000+((AK24-500000000)*30%),IF(AK24>5000000000,(1444000000+(AK24-5000000000)*35%)))))) -> 255050 | AM24: =+AL24/12 -> 21254.167
A25: 17 | B25: VIRYA ADELIA SAVITRI | C25: 12 | D25: ADM | E25: TK | F25: 3201024209970007 | G25: 4877211 | I25: 200000 | J25: 0 | K25: 0 | L25: 0 | N25: =SUM(G25:M25) -> 5077211 | O25: =+AD25*$O$7 -> 58038.811 | P25: =+AD25*$P$7 -> 97544.22 | Q25: =+AD25*$Q$7 -> 97544.22 | R25: =+AE25*$R$7 -> 203088.44 | S25: =SUM(O25:R25) -> 456215.69 | T25: =+N25+S25 -> 5533426.7 | U25: =+AD25*$U$7 -> 97544.22 | V25: =+AD25*$V$7 -> 48772.11 | W25: =+AE25*$W$7 -> 50772.11 | X25: 0 | Y25: =SUM(U25:X25) -> 197088.44 | Z25: 0 | AA25: =+N25-Y25-Z25 -> 4880122.6 | AD25: =+G25 -> 4877211 | AE25: =+N25 -> 5077211 | AF25: =+N25+O25+R25 -> 5338338.3 | AG25: =IF(AF25*$AG$7>500000,500000,AF25*$AG$7) -> 266916.91 | AH25: =+AF25-AG25-U25-V25 -> 4925105 | AI25: =+AH25*$AI$7 -> 59101260 | AJ25: =IF(E25="TK",54000000,(IF(OR(E25="TK1",E25="K"),58500000,(IF(OR(E25="TK2",E25="K1"),63000000,(IF(OR(OR(E25="TK3",E25="TK4"),E25="K2"),67500000,72000000))))))) -> 54000000 | AK25: =IF((+AI25-AJ25)<=0,0,TRUNC((AI25-AJ25)/1000)*1000) -> 5101000 | AL25: =IF(AK25<=60000000,AK25*5%,IF(AK25<=250000000,3000000+((AK25-60000000)*15%),IF(AK25<=500000000,31500000+((AK25-250000000)*25%),IF(AND(AK25>=500000000,AK25<=5000000000),94000000+((AK25-500000000)*30%),IF(AK25>5000000000,(1444000000+(AK25-5000000000)*35%)))))) -> 255050 | AM25: =+AL25/12 -> 21254.167
A26: 18 | B26: ZASKIA EVA | C26: 12 | D26: ADM | E26: TK | F26: 3602206110020001 | G26: 4877211 | I26: 200000 | J26: 0 | K26: 0 | L26: 0 | N26: =SUM(G26:M26) -> 5077211 | O26: =+AD26*$O$7 -> 58038.811 | P26: =+AD26*$P$7 -> 97544.22 | Q26: =+AD26*$Q$7 -> 97544.22 | R26: =+AE26*$R$7 -> 203088.44 | S26: =SUM(O26:R26) -> 456215.69 | T26: =+N26+S26 -> 5533426.7 | U26: =+AD26*$U$7 -> 97544.22 | V26: =+AD26*$V$7 -> 48772.11 | W26: =+AE26*$W$7 -> 50772.11 | X26: 0 | Y26: =SUM(U26:X26) -> 197088.44 | Z26: 0 | AA26: =+N26-Y26-Z26 -> 4880122.6 | AD26: =+G26 -> 4877211 | AE26: =+N26 -> 5077211 | AF26: =+N26+O26+R26 -> 5338338.3 | AG26: =IF(AF26*$AG$7>500000,500000,AF26*$AG$7) -> 266916.91 | AH26: =+AF26-AG26-U26-V26 -> 4925105 | AI26: =+AH26*$AI$7 -> 59101260 | AJ26: =IF(E26="TK",54000000,(IF(OR(E26="TK1",E26="K"),58500000,(IF(OR(E26="TK2",E26="K1"),63000000,(IF(OR(OR(E26="TK3",E26="TK4"),E26="K2"),67500000,72000000))))))) -> 54000000 | AK26: =IF((+AI26-AJ26)<=0,0,TRUNC((AI26-AJ26)/1000)*1000) -> 5101000 | AL26: =IF(AK26<=60000000,AK26*5%,IF(AK26<=250000000,3000000+((AK26-60000000)*15%),IF(AK26<=500000000,31500000+((AK26-250000000)*25%),IF(AND(AK26>=500000000,AK26<=5000000000),94000000+((AK26-500000000)*30%),IF(AK26>5000000000,(1444000000+(AK26-5000000000)*35%)))))) -> 255050 | AM26: =+AL26/12 -> 21254.167
W27: =SUM(W9:W27) -> 0
A28: SUB TOTAL | G28: =SUM(G9:G27) -> 125616509 | H28: =SUM(H9:H27) -> 0 | I28: =SUM(I9:I27) -> 5500000 | J28: =SUM(J10:J27) -> 0 | K28: =SUM(K8:K27) -> 0 | L28: =SUM(L9:L27) -> 0 | M28: =SUM(M9:M27) -> 0 | N28: =SUM(N9:N27) -> 131116509 | O28: =SUM(O9:O27) -> 1393686.5 | P28: =SUM(P9:P27) -> 2342330.2 | Q28: =SUM(Q9:Q27) -> 2342330.2 | R28: =SUM(R9:R27) -> 5244660.4 | S28: =SUM(S9:S27) -> 11323007 | ... V28: =SUM(V9:V27) -> 1171165.1 | W28: =SUM(W9:W26) -> 1311165.1 | X28: =SUM(X9:X27) -> 578871.48 | Y28: =SUM(Y9:Y27) -> 5307600.8 | Z28: =SUM(Z9:Z27) -> 1652454 | AA28: =SUM(AA9:AA27) -> 1.2415645e+08
N29: =+T28 -> 1.4243952e+08 | S29: =+O28+P28+Q28+U28+V28 -> 9495911.1 | T29: =+R28+W28+X28 -> 7134696.9 | Z29: =+Z28 -> 1652454 | AA29: =+AA28 -> 1.2415645e+08

Sheet SLIP-STAFF
B5: SLIP GAJI | L5: SLIP GAJI
B6: No. Urut | C6: : | D6: ='[2]G-STAFF'!A8 -> 1 | L6: No. Urut | M6: : | N6: ='[2]G-STAFF'!A9 -> 2
B7: Periode | C7: : | D7: ='[2]G-STAFF'!A3 -> 01 JANUARI S/D 31 JANUARI 2025 | L7: Periode | M7: : | N7: ='[2]G-STAFF'!A3 -> 01 JANUARI S/D 31 JANUARI 2025
B8: Nama Karyawan | C8: : | D8: ='[2]G-STAFF'!B8 -> EDDY SILALAHI, SE | L8: Nama Karyawan | M8: : | N8: ='[2]G-STAFF'!B9 -> KUSUMA DWI PRABASARI
B9: Bagian / Jabatan | C9: : | D9: ='[2]G-STAFF'!H8 -> CHIEF ACC. | L9: Bagian / Jabatan | M9: : | N9: ='[2]G-STAFF'!H9 -> PPIC/MARKETING
B11: PENERIMAAN | L11: PENERIMAAN
B12: GAJI POKOK | H12: ='[2]G-STAFF'!J8 -> 8500000 | L12: GAJI POKOK | R12: =+STAFF!G10 -> 9450558
B13: TUNJANGAN JABATAN | H13: =+STAFF!I9 -> 0 | L13: TUNJANGAN JABATAN | R13: =+STAFF!I10 -> 500000
B14: TUNJANGAN BPJS | H14: =+STAFF!S9 -> 340000 | L14: TUNJANGAN BPJS | R14: =+STAFF!S10 -> 888506.28
B15: UANG MAKAN | D15: 0 | E15: H.K | F15: X | G15: 0 | H15: =G15*D15 -> 0 | L15: UANG MAKAN | N15: 0 | O15: H.K | P15: X | Q15: 0 | R15: =Q15*N15 -> 0
B16: HL/HM/HR | D16: ='[2]G-STAFF'!CH8 -> 0 | E16: JAM | F16: X | G16: ='[2]G-STAFF'!M8 -> 0 | H16: =G16*D16 -> 0 | L16: HL/HM/HR | N16: ='[2]G-STAFF'!CO8 -> 0 | O16: JAM | P16: X | Q16: ='[2]G-STAFF'!M9 -> 0 | R16: =Q16*N16 -> 0
B17: H.BIASA | D17: ='[2]G-STAFF'!CG8 -> 0 | E17: JAM | F17: X | G17: =G16 -> 0 | H17: =G17*D17 -> 0 | L17: H.BIASA | N17: ='[2]G-STAFF'!CN8 -> 0 | O17: JAM | P17: X | Q17: =Q16 -> 0 | R17: =Q17*N17 -> 0
B18: TOTAL GAJI | D18: ='[2]G-STAFF'!CI8 -> 0 | H18: =SUM(H12:H17) -> 8840000 | L18: TOTAL GAJI | N18: ='[2]G-STAFF'!CP8 -> 0 | R18: =SUM(R12:R17) -> 10839064
B20: POTONGAN | L20: POTONGAN
B21: PPH 21 | G21: ='[2]G-STAFF'!C8 -> K1 | H21: =+STAFF!Z9 -> 88400 | L21: PPH 21 | Q21: ='[2]G-STAFF'!C9 -> TK | R21: =+STAFF!Z10 -> 261526
B22: BPJS KES 1% | H22: =+STAFF!W9+STAFF!X9 -> 85000 | L22: BPJS KES 1% | R22: =+STAFF!X10+STAFF!W10 -> 99505.58
B23: BPJS TK 3% | H23: =+STAFF!U9+STAFF!V9 -> 0 | L23: BPJS TK 3% | R23: =+STAFF!U10+STAFF!V10 -> 283516.74
B24: BPJS DITANGGUNG PERUSAHAAN | H24: =+H14 -> 340000 | L24: BPJS DITANGGUNG PERUSAHAAN | R24: =+R14 -> 888506.28
B25: TOTAL POTONGAN | H25: =SUM(H21:H24) -> 513400 | L25: TOTAL POTONGAN | R25: =SUM(R21:R24) -> 1533054.6
B26: TOTAL GAJI DITERIMA | H26: =SUM(H18-H25) -> 8326600 | L26: TOTAL GAJI DITERIMA | R26: =SUM(R18-R25) -> 9306009.7
B27: DIBUAT | G27: DITERIMA | L27: DIBUAT | Q27: DITERIMA
B30: (__________________) | G30: (________________) | L30: (__________________) | Q30: (________________)
B37: SLIP GAJI | L37: SLIP GAJI
B38: No. Urut | C38: : | D38: ='[2]G-STAFF'!A10 -> 3 | L38: No. Urut | M38: : | N38: ='[2]G-STAFF'!A11 -> 4
B39: Periode | C39: : | D39: ='[2]G-STAFF'!A3 -> 01 JANUARI S/D 31 JANUARI 2025 | L39: Periode | M39: : | N39: ='[2]G-STAFF'!A3 -> 01 JANUARI S/D 31 JANUARI 2025
B40: Nama Karyawan | C40: : | D40: ='[2]G-STAFF'!B10 -> ERNI NURAENI | L40: Nama Karyawan | M40: : | N40: ='[2]G-STAFF'!B11 -> SRI WAHYUNI
B41: Bagian / Jabatan | C41: : | D41: ='[2]G-STAFF'!H10 -> PPIC/MARKETING | L41: Bagian / Jabatan | M41: : | N41: ='[2]G-STAFF'!H11 -> PERSONALIA
B43: PENERIMAAN | L43: PENERIMAAN
B44: GAJI POKOK | H44: =+STAFF!G11 -> 7845749 | L44: GAJI POKOK | R44: =+STAFF!G12 -> 10106032
B45: TUNJANGAN JABATAN | H45: =+STAFF!I11 -> 300000 | L45: TUNJANGAN JABATAN | R45: =+STAFF!I12 -> 700000
B46: TUNJANGAN BPJS | H46: =+STAFF!S11 -> 733024.33 | L46: TUNJANGAN BPJS | R46: =+STAFF!S12 -> 956744.34
B47: UANG MAKAN | D47: 0 | E47: H.K | F47: X | G47: 0 | L47: UANG MAKAN | N47: 0 | O47: H.K | P47: X | Q47: 0 | R47: =Q47*N47 -> 0
B48: HL/HM/HR | D48: ='[2]G-STAFF'!CH9 -> 0 | E48: JAM | F48: X | G48: ='[2]G-STAFF'!M10 -> 0 | H48: =G48*D48 -> 0 | L48: HL/HM/HR | N48: ='[2]G-STAFF'!CH10 -> 0 | O48: JAM | P48: X | Q48: ='[2]G-STAFF'!M11 -> 0 | R48: =Q48*N48 -> 0
B49: H.BIASA | D49: ='[2]G-STAFF'!CG9 -> 0 | E49: JAM | F49: X | G49: =G48 -> 0 | H49: =G49*D49 -> 0 | L49: H.BIASA | N49: ='[2]G-STAFF'!CG10 -> 0 | O49: JAM | P49: X | Q49: =Q48 -> 0 | R49: =Q49*N49 -> 0
B50: TOTAL GAJI | D50: =SUM(D47:D49) -> 0 | H50: =SUM(H44:H49) -> 8878773.3 | L50: TOTAL GAJI | N50: =SUM(N48:N49) -> 0 | R50: =SUM(R44:R49) -> 11762776
B52: POTONGAN | L52: POTONGAN
B53: PPH 21 | G53: ='[2]G-STAFF'!C10 -> TK | H53: =+STAFF!Z11 -> 149887 | L53: PPH 21 | Q53: ='[2]G-STAFF'!C11 -> TK | R53: =+STAFF!Z12 -> 397549
B54: BPJS KES 1% | H54: =+STAFF!W11+STAFF!X11 -> 162914.98 | L54: BPJS KES 1% | R54: =+STAFF!W12+STAFF!X12 -> 216120.64
B55: BPJS TK 3% | H55: =+STAFF!U11+STAFF!V11 -> 235372.47 | L55: BPJS TK 3% | R55: =+STAFF!U12+STAFF!V12 -> 207249.96
B56: BPJS DITANGGUNG PERUSAHAAN | H56: =+H46 -> 733024.33 | L56: BPJS DITANGGUNG PERUSAHAAN | R56: =+R46 -> 956744.34
...

Sheet GENERAL
A1: PT INDOBOX UTAMA JAYA
A2: DAFTAR GAJI GENERAL
A3: PERIODE 01 NOVEMBER S/D 30 NOVEMBER 2025
B5: 1 | C5: 3 | D5: 4 | E5: 5 | F5: 6 | G5: 7 | H5: 8 | I5: 9 | J5: 10 | K5: 11 | L5: 12 | M5: 13 | N5: 14 | O5: 15 | P5: 16 | Q5: 17 | R5: 18 | S5: 19 | T5: 20 | U5: 21 | V5: 22 | W5: 23 | X5: 24 | Y5: 25 | Z5: 26 | AA5: 27 | AB5: 28
A6: NO | B6: NAMA | C6: JABATAN | D6: STS | E6: NIK | F6: GAJI POKOK | G6: JAM OT | H6: OT / JAM | I6: LEMBUR | J6: TUNJANGAN | O6: TOTAL GAJI | P6: BPJS DITANGGUNG PERUSAHAAN | T6: BPJS PER- USAHAAN | U6: GAJI BRUTO | V6: BPJS DITANGGUNG KARYAWAN | Z6: POTONGAN | AB6: Gaji Setelah PPh 21 | AE6: BPJS TK | AF6: JKN | AG6: GAJI BRUTO | AH6: BIAYA JABATAN | AI6: GAJI NETTO | AJ6: GAJI SETAHUN | AK6: PTKP | AL6: PKP | AM6: PPH 21 SETAHUN | AN6: PPH 21 SEBULAN
J7: UANG JABATAN | K7: PRESTASI | L7: BONUS | M7: UANG | N7: THR/ | P7: JKK JKM | Q7: JHT | R7: JP | S7: BPJS KES | V7: JHT | W7: JP | X7: BPJS KES | Y7: TAMBAHAN | Z7: BPJS | AA7: PPh 21
M8: MAKAN | N8: BONUS | P8: 0.0119 | Q8: 0.02 | R8: 0.02 | S8: 0.04 | V8: 0.02 | W8: 0.01 | X8: 0.01 | Y8: 0.01 | Z8: TK + KES | AB8: (THP) | AH8: 0.05 | AJ8: 12
A10: 1 | B10: DEDE IRAWAN | C10: SECURITY | D10: K1 | E10: 3201021703840004 | F10: 4877211 | G10: 0 | H10: =+F10/173 -> 28191.971 | I10: =+G10*H10 -> 0 | J10: 0 | K10: 0 | M10: 180000 | O10: =+F10+I10+J10+K10+M10+N10 -> 5057211 | P10: =+AE10*$P$8 -> 58038.811 | Q10: =+AE10*$Q$8 -> 97544.22 | R10: =+AE10*$R$8 -> 97544.22 | S10: =+AF10*$S$8 -> 195088.44 | T10: =SUM(P10:S10) -> 448215.69 | U10: =+O10+T10 -> 5505426.7 | V10: =+AE10*$V$8 -> 97544.22 | W10: =+AE10*$W$8 -> 48772.11 | X10: =+AF10*$X$8 -> 48772.11 | Y10: 0 | Z10: =SUM(V10:Y10) -> 195088.44 | AA10: 0 | AB10: =+O10-Z10-AA10 -> 4862122.6 | AE10: =+F10 -> 4877211 | AF10: 4877211 | AG10: =+O10+P10+S10 -> 5310338.3 | AH10: =IF(AG10*0.05>500000,500000,AG10*0.05) -> 265516.91 | AI10: =+AG10-AH10-V10-W10 -> 4898505 | AJ10: =+AI10*$AJ$8 -> 58782060 | AK10: =IF(D10="TK",54000000,(IF(OR(D10="TK1",D10="K"),58500000,(IF(OR(D10="TK2",D10="K1"),63000000,(IF(OR(OR(D10="TK3",D10="TK4"),D10="K2"),67500000,72000000))))))) -> 63000000 | AL10: =IF((+AJ10-AK10)<=0,0,TRUNC((AJ10-AK10)/1000)*1000) -> 0 | AM10: =IF(AL10<=60000000,AL10*5%,IF(AL10<=250000000,3000000+((AL10-60000000)*15%),IF(AL10<=500000000,31500000+((AL10-250000000)*25%),IF(AND(AL10>=500000000,AL10<=5000000000),94000000+((AL10-500000000)*30%),IF(AL10>5000000000,(1444000000+(AL10-5000000000)*35%)))))) -> 0 | AN10: =+AM10/12 -> 0
A11: 2 | B11: DONI IMAM SAPUTRO | C11: SECURITY | D11: TK | E11: 3201020202800004 | F11: 4594855 | G11: 0 | H11: =+F11/173 -> 26559.855 | I11: =+G11*H11 -> 0 | J11: 0 | K11: 0 | M11: 180000 | O11: =+F11+I11+J11+K11+M11+N11 -> 4774855 | P11: =+AE11*$P$8 -> 58038.811 | Q11: =+AE11*$Q$8 -> 97544.22 | R11: =+AE11*$R$8 -> 97544.22 | S11: =+AF11*$S$8 -> 195088.44 | T11: =SUM(P11:S11) -> 448215.69 | U11: =+O11+T11 -> 5223070.7 | V11: =+AE11*$V$8 -> 97544.22 | W11: =+AE11*$W$8 -> 48772.11 | X11: =+AF11*$X$8 -> 48772.11 | Y11: 0 | Z11: =SUM(V11:Y11) -> 195088.44 | AA11: 0 | AB11: =+O11-Z11-AA11 -> 4579766.6 | AE11: 4877211 | AF11: 4877211 | AG11: =+O11+P11+S11 -> 5027982.3 | AH11: =IF(AG11*0.05>500000,500000,AG11*0.05) -> 251399.11 | AI11: =+AG11-AH11-V11-W11 -> 4630266.8 | AJ11: =+AI11*$AJ$8 -> 55563202 | AK11: =IF(D11="TK",54000000,(IF(OR(D11="TK1",D11="K"),58500000,(IF(OR(D11="TK2",D11="K1"),63000000,(IF(OR(OR(D11="TK3",D11="TK4"),D11="K2"),67500000,72000000))))))) -> 54000000 | AL11: =IF((+AJ11-AK11)<=0,0,TRUNC((AJ11-AK11)/1000)*1000) -> 1563000 | AM11: =IF(AL11<=60000000,AL11*5%,IF(AL11<=250000000,3000000+((AL11-60000000)*15%),IF(AL11<=500000000,31500000+((AL11-250000000)*25%),IF(AND(AL11>=500000000,AL11<=5000000000),94000000+((AL11-500000000)*30%),IF(AL11>5000000000,(1444000000+(AL11-5000000000)*35%)))))) -> 78150 | AN11: =+AM11/12 -> 6512.5
A12: 3 | B12: ANDIKA WIJAYA | C12: SECURITY | D12: K1 | E12: 3201020107710001 | F12: 4594855 | G12: 0 | H12: =+F12/173 -> 26559.855 | I12: =+G12*H12 -> 0 | J12: 0 | K12: 0 | M12: 180000 | O12: =+F12+I12+J12+K12+M12+N12 -> 4774855 | P12: =+AE12*$P$8 -> 58038.811 | Q12: =+AE12*$Q$8 -> 97544.22 | R12: =+AE12*$R$8 -> 97544.22 | S12: =+AF12*$S$8 -> 195088.44 | T12: =SUM(P12:S12) -> 448215.69 | U12: =+O12+T12 -> 5223070.7 | V12: =+AE12*$V$8 -> 97544.22 | W12: =+AE12*$W$8 -> 48772.11 | X12: =+AF12*$X$8 -> 48772.11 | Y12: 0 | Z12: =SUM(V12:Y12) -> 195088.44 | AA12: 0 | AB12: =+O12-Z12-AA12 -> 4579766.6 | AE12: 4877211 | AF12: 4877211 | AG12: =+O12+P12+S12 -> 5027982.3 | AH12: =IF(AG12*0.05>500000,500000,AG12*0.05) -> 251399.11 | AI12: =+AG12-AH12-V12-W12 -> 4630266.8 | AJ12: =+AI12*$AJ$8 -> 55563202 | AK12: =IF(D12="TK",54000000,(IF(OR(D12="TK1",D12="K"),58500000,(IF(OR(D12="TK2",D12="K1"),63000000,(IF(OR(OR(D12="TK3",D12="TK4"),D12="K2"),67500000,72000000))))))) -> 63000000 | AL12: =IF((+AJ12-AK12)<=0,0,TRUNC((AJ12-AK12)/1000)*1000) -> 0 | AM12: =IF(AL12<=60000000,AL12*5%,IF(AL12<=250000000,3000000+((AL12-60000000)*15%),IF(AL12<=500000000,31500000+((AL12-250000000)*25%),IF(AND(AL12>=500000000,AL12<=5000000000),94000000+((AL12-500000000)*30%),IF(AL12>5000000000,(1444000000+(AL12-5000000000)*35%)))))) -> 0 | AN12: =+AM12/12 -> 0
A13: 4 | B13: SAMANHUDI | C13: SECURITY | D13: K | E13: 3201022401830001 | F13: 4594855 | G13: 0 | H13: =+F13/173 -> 26559.855 | I13: =+G13*H13 -> 0 | J13: 0 | K13: 0 | M13: 180000 | O13: =+F13+I13+J13+K13+M13+N13 -> 4774855 | P13: =+AE13*$P$8 -> 58038.811 | Q13: =+AE13*$Q$8 -> 97544.22 | R13: =+AE13*$R$8 -> 97544.22 | S13: =+AF13*$S$8 -> 195088.44 | T13: =SUM(P13:S13) -> 448215.69 | U13: =+O13+T13 -> 5223070.7 | V13: =+AE13*$V$8 -> 97544.22 | W13: =+AE13*$W$8 -> 48772.11 | X13: =+AF13*$X$8 -> 48772.11 | Y13: 0 | Z13: =SUM(V13:Y13) -> 195088.44 | AA13: 0 | AB13: =+O13-Z13-AA13 -> 4579766.6 | AE13: 4877211 | AF13: 4877211 | AG13: =+O13+P13+S13 -> 5027982.3 | AH13: =IF(AG13*0.05>500000,500000,AG13*0.05) -> 251399.11 | AI13: =+AG13-AH13-V13-W13 -> 4630266.8 | AJ13: =+AI13*$AJ$8 -> 55563202 | AK13: =IF(D13="TK",54000000,(IF(OR(D13="TK1",D13="K"),58500000,(IF(OR(D13="TK2",D13="K1"),63000000,(IF(OR(OR(D13="TK3",D13="TK4"),D13="K2"),67500000,72000000))))))) -> 58500000 | AL13: =IF((+AJ13-AK13)<=0,0,TRUNC((AJ13-AK13)/1000)*1000) -> 0 | AM13: =IF(AL13<=60000000,AL13*5%,IF(AL13<=250000000,3000000+((AL13-60000000)*15%),IF(AL13<=500000000,31500000+((AL13-250000000)*25%),IF(AND(AL13>=500000000,AL13<=5000000000),94000000+((AL13-500000000)*30%),IF(AL13>5000000000,(1444000000+(AL13-5000000000)*35%)))))) -> 0 | AN13: =+AM13/12 -> 0
A14: 5 | B14: MAIZENDY SAPTA PUTRA | C14: MEKANIK | D14: K2 | F14: 4877211 | G14: 0 | H14: =+F14/173 -> 28191.971 | I14: =+G14*H14 -> 0 | J14: 300000 | K14: 0 | M14: 150000 | O14: =+F14+I14+J14+K14+M14+N14 -> 5327211 | P14: =+AE14*$P$8 -> 58038.811 | Q14: =+AE14*$Q$8 -> 97544.22 | R14: =+AE14*$R$8 -> 97544.22 | S14: =+AF14*$S$8 -> 195088.44 | T14: =SUM(P14:S14) -> 448215.69 | U14: =+O14+T14 -> 5775426.7 | V14: =+AE14*$V$8 -> 97544.22 | W14: =+AE14*$W$8 -> 48772.11 | X14: =+AF14*$X$8 -> 48772.11 | Y14: 0 | Z14: =SUM(V14:Y14) -> 195088.44 | AA14: 0 | AB14: =+O14-Z14-AA14 -> 5132122.6 | AE14: =+F14 -> 4877211 | AF14: =+F14 -> 4877211 | AG14: =+O14+P14+S14 -> 5580338.3 | AH14: =IF(AG14*0.05>500000,500000,AG14*0.05) -> 279016.91 | AI14: =+AG14-AH14-V14-W14 -> 5155005 | AJ14: =+AI14*$AJ$8 -> 61860060 | AK14: =IF(D14="TK",54000000,(IF(OR(D14="TK1",D14="K"),58500000,(IF(OR(D14="TK2",D14="K1"),63000000,(IF(OR(OR(D14="TK3",D14="TK4"),D14="K2"),67500000,72000000))))))) -> 67500000 | AL14: =IF((+AJ14-AK14)<=0,0,TRUNC((AJ14-AK14)/1000)*1000) -> 0 | AM14: =IF(AL14<=60000000,AL14*5%,IF(AL14<=250000000,3000000+((AL14-60000000)*15%),IF(AL14<=500000000,31500000+((AL14-250000000)*25%),IF(AND(AL14>=500000000,AL14<=5000000000),94000000+((AL14-500000000)*30%),IF(AL14>5000000000,(1444000000+(AL14-5000000000)*35%)))))) -> 0 | AN14: =+AM14/12 -> 0
A15: 6 | B15: SUTRIS | C15: DRIVER | D15: K1 | E15: 3324030803700004 | F15: 4877211 | G15: 42 | H15: =+F15/173 -> 28191.971 | I15: =+G15*H15 -> 1184062.8 | J15: 100000 | K15: 0 | M15: 114000 | O15: =+F15+I15+J15+K15+M15+N15 -> 6275273.8 | P15: =+AE15*$P$8 -> 58038.811 | Q15: =+AE15*$Q$8 -> 97544.22 | R15: =+AE15*$R$8 -> 97544.22 | S15: =+AF15*$S$8 -> 195088.44 | T15: =SUM(P15:S15) -> 448215.69 | U15: =+O15+T15 -> 6723489.5 | V15: =+AE15*$V$8 -> 97544.22 | W15: =+AE15*$W$8 -> 48772.11 | X15: =+AF15*$X$8 -> 48772.11 | Y15: 0 | Z15: =SUM(V15:Y15) -> 195088.44 | AA15: 32642 | AB15: =+O15-Z15-AA15 -> 6047543.3 | AE15: 4877211 | AF15: 4877211 | AG15: =+O15+P15+S15 -> 6528401 | AH15: =IF(AG15*0.05>500000,500000,AG15*0.05) -> 326420.05 | AI15: =+AG15-AH15-V15-W15 -> 6055664.7 | AJ15: =+AI15*$AJ$8 -> 72667976 | AK15: =IF(D15="TK",54000000,(IF(OR(D15="TK1",D15="K"),58500000,(IF(OR(D15="TK2",D15="K1"),63000000,(IF(OR(OR(D15="TK3",D15="TK4"),D15="K2"),67500000,72000000))))))) -> 63000000 | AL15: =IF((+AJ15-AK15)<=0,0,TRUNC((AJ15-AK15)/1000)*1000) -> 9667000 | AM15: =IF(AL15<=60000000,AL15*5%,IF(AL15<=250000000,3000000+((AL15-60000000)*15%),IF(AL15<=500000000,31500000+((AL15-250000000)*25%),IF(AND(AL15>=500000000,AL15<=5000000000),94000000+((AL15-500000000)*30%),IF(AL15>5000000000,(1444000000+(AL15-5000000000)*35%)))))) -> 483350 | AN15: =+AM15/12 -> 40279.167
A16: 7 | B16: SUCIPTO | C16: DRIVER | D16: K | E16: 3201020607720008 | F16: 4877211 | G16: 29 | H16: =+F16/173 -> 28191.971 | I16: =+G16*H16 -> 817567.16 | J16: 0 | K16: 0 | M16: 120000 | O16: =+F16+I16+J16+K16+M16+N16 -> 5814778.2 | P16: =+AE16*$P$8 -> 58038.811 | Q16: =+AE16*$Q$8 -> 97544.22 | R16: =+AE16*$R$8 -> 97544.22 | S16: =+AF16*$S$8 -> 195088.44 | T16: =SUM(P16:S16) -> 448215.69 | U16: =+O16+T16 -> 6262993.9 | V16: =+AE16*$V$8 -> 97544.22 | W16: =+AE16*$W$8 -> 48772.11 | X16: =+AF16*$X$8 -> 48772.11 | Y16: 0 | Z16: =SUM(V16:Y16) -> 195088.44 | AA16: 45509 | AB16: =+O16-Z16-AA16 -> 5574180.7 | AE16: 4877211 | AF16: 4877211 | AG16: =+O16+P16+S16 -> 6067905.4 | AH16: =IF(AG16*0.05>500000,500000,AG16*0.05) -> 303395.27 | AI16: =+AG16-AH16-V16-W16 -> 5618193.8 | AJ16: =+AI16*$AJ$8 -> 67418326 | AK16: =IF(D16="TK",54000000,(IF(OR(D16="TK1",D16="K"),58500000,(IF(OR(D16="TK2",D16="K1"),63000000,(IF(OR(OR(D16="TK3",D16="TK4"),D16="K2"),67500000,72000000))))))) -> 58500000 | AL16: =IF((+AJ16-AK16)<=0,0,TRUNC((AJ16-AK16)/1000)*1000) -> 8918000 | AM16: =IF(AL16<=60000000,AL16*5%,IF(AL16<=250000000,3000000+((AL16-60000000)*15%),IF(AL16<=500000000,31500000+((AL16-250000000)*25%),IF(AND(AL16>=500000000,AL16<=5000000000),94000000+((AL16-500000000)*30%),IF(AL16>5000000000,(1444000000+(AL16-5000000000)*35%)))))) -> 445900 | AN16: =+AM16/12 -> 37158.333
A17: 8 | B17: UDI | C17: DRIVER | D17: K1 | E17: 3174073005740007 | F17: 4594855 | G17: 140.5 | H17: =+F17/173 -> 26559.855 | I17: =+G17*H17 -> 3731659.7 | J17: 0 | K17: 0 | M17: 90000 | O17: =+F17+I17+J17+K17+M17+N17 -> 8416514.7 | P17: =+AE17*$P$8 -> 58038.811 | Q17: =+AE17*$Q$8 -> 97544.22 | R17: =+AE17*$R$8 -> 97544.22 | S17: =+AF17*$S$8 -> 195088.44 | T17: =SUM(P17:S17) -> 448215.69 | U17: =+O17+T17 -> 8864730.4 | V17: =+AE17*$V$8 -> 97544.22 | W17: =+AE17*$W$8 -> 48772.11 | X17: =+AF17*$X$8 -> 48772.11 | Y17: 0 | Z17: =SUM(V17:Y17) -> 195088.44 | AA17: 86696 | AB17: =+O17-Z17-AA17 -> 8134730.3 | AE17: 4877211 | AF17: 4877211 | AG17: =+O17+P17+S17 -> 8669641.9 | AH17: =IF(AG17*0.05>500000,500000,AG17*0.05) -> 433482.1 | AI17: =+AG17-AH17-V17-W17 -> 8089843.5 | AJ17: =+AI17*$AJ$8 -> 97078122 | AK17: =IF(D17="TK",54000000,(IF(OR(D17="TK1",D17="K"),58500000,(IF(OR(D17="TK2",D17="K1"),63000000,(IF(OR(OR(D17="TK3",D17="TK4"),D17="K2"),67500000,72000000))))))) -> 63000000 | AL17: =IF((+AJ17-AK17)<=0,0,TRUNC((AJ17-AK17)/1000)*1000) -> 34078000 | AM17: =IF(AL17<=60000000,AL17*5%,IF(AL17<=250000000,3000000+((AL17-60000000)*15%),IF(AL17<=500000000,31500000+((AL17-250000000)*25%),IF(AND(AL17>=500000000,AL17<=5000000000),94000000+((AL17-500000000)*30%),IF(AL17>5000000000,(1444000000+(AL17-5000000000)*35%)))))) -> 1703900 | AN17: =+AM17/12 -> 141991.67
A18: 9 | B18: ANDI | C18: DRIVER | D18: K1 | E18: 3201022704740002 | F18: 4594855 | G18: 37 | H18: =+F18/173 -> 26559.855 | I18: =+G18*H18 -> 982714.65 | J18: 0 | K18: 0 | M18: 114000 | O18: =+F18+I18+J18+K18+M18+N18 -> 5691569.7 | P18: =+AE18*$P$8 -> 58038.811 | Q18: =+AE18*$Q$8 -> 97544.22 | R18: =+AE18*$R$8 -> 97544.22 | S18: =+AF18*$S$8 -> 195088.44 | T18: =SUM(P18:S18) -> 448215.69 | U18: =+O18+T18 -> 6139785.3 | V18: =+AE18*$V$8 -> 97544.22 | W18: =+AE18*$W$8 -> 48772.11 | X18: =+AF18*$X$8 -> 48772.11 | Y18: 0 | Z18: =SUM(V18:Y18) -> 195088.44 | AA18: 0 | AB18: =+O18-Z18-AA18 -> 5496481.2 | AE18: 4877211 | AF18: 4877211 | AG18: =+O18+P18+S18 -> 5944696.9 | AH18: =IF(AG18*0.05>500000,500000,AG18*0.05) -> 297234.85 | AI18: =+AG18-AH18-V18-W18 -> 5501145.7 | AJ18: =+AI18*$AJ$8 -> 66013749 | AK18: =IF(D18="TK",54000000,(IF(OR(D18="TK1",D18="K"),58500000,(IF(OR(D18="TK2",D18="K1"),63000000,(IF(OR(OR(D18="TK3",D18="TK4"),D18="K2"),67500000,72000000))))))) -> 63000000 | AL18: =IF((+AJ18-AK18)<=0,0,TRUNC((AJ18-AK18)/1000)*1000) -> 3013000 | AM18: =IF(AL18<=60000000,AL18*5%,IF(AL18<=250000000,3000000+((AL18-60000000)*15%),IF(AL18<=500000000,31500000+((AL18-250000000)*25%),IF(AND(AL18>=500000000,AL18<=5000000000),94000000+((AL18-500000000)*30%),IF(AL18>5000000000,(1444000000+(AL18-5000000000)*35%)))))) -> 150650 | AN18: =+AM18/12 -> 12554.167
A19: 10 | B19: SAIPUL ANWAR | C19: DRIVER | D19: K1 | E19: 3201020305850006 | F19: 4494855 | G19: 54.5 | H19: =+F19/173 -> 25981.821 | I19: =+G19*H19 -> 1416009.2 | J19: 0 | K19: 0 | M19: 114000 | O19: =+F19+I19+J19+K19+M19+N19 -> 6024864.2 | P19: =+AE19*$P$8 -> 58038.811 | Q19: =+AE19*$Q$8 -> 97544.22 | R19: =+AE19*$R$8 -> 97544.22 | S19: =+AF19*$S$8 -> 195088.44 | T19: =SUM(P19:S19) -> 448215.69 | U19: =+O19+T19 -> 6473079.9 | V19: =+AE19*$V$8 -> 97544.22 | W19: =+AE19*$W$8 -> 48772.11 | X19: =+AF19*$X$8 -> 48772.11 | Y19: 0 | Z19: =SUM(V19:Y19) -> 195088.44 | AA19: 33988 | AB19: =+O19-Z19-AA19 -> 5795787.8 | AE19: 4877211 | AF19: 4877211 | AG19: =+O19+P19+S19 -> 6277991.5 | AH19: =IF(AG19*0.05>500000,500000,AG19*0.05) -> 313899.57 | AI19: =+AG19-AH19-V19-W19 -> 5817775.6 | AJ19: =+AI19*$AJ$8 -> 69813307 | AK19: =IF(D19="TK",54000000,(IF(OR(D19="TK1",D19="K"),58500000,(IF(OR(D19="TK2",D19="K1"),63000000,(IF(OR(OR(D19="TK3",D19="TK4"),D19="K2"),67500000,72000000))))))) -> 63000000 | AL19: =IF((+AJ19-AK19)<=0,0,TRUNC((AJ19-AK19)/1000)*1000) -> 6813000 | AM19: =IF(AL19<=60000000,AL19*5%,IF(AL19<=250000000,3000000+((AL19-60000000)*15%),IF(AL19<=500000000,31500000+((AL19-250000000)*25%),IF(AND(AL19>=500000000,AL19<=5000000000),94000000+((AL19-500000000)*30%),IF(AL19>5000000000,(1444000000+(AL19-5000000000)*35%)))))) -> 340650 | AN19: =+AM19/12 -> 28387.5
A20: 11 | B20: ZULKARNAEN | C20: DRIVER | D20: K2 | E20: 3201322411930002 | F20: 4494855 | G20: 44.5 | H20: =+F20/173 -> 25981.821 | I20: =+G20*H20 -> 1156191 | J20: 0 | K20: 0 | M20: 102000 | O20: =+F20+I20+J20+K20+M20+N20 -> 5753046 | P20: =+AE20*$P$8 -> 58038.811 | Q20: =+AE20*$Q$8 -> 97544.22 | R20: =+AE20*$R$8 -> 97544.22 | S20: =+AF20*$S$8 -> 195088.44 | T20: =SUM(P20:S20) -> 448215.69 | U20: =+O20+T20 -> 6201261.7 | V20: =+AE20*$V$8 -> 97544.22 | W20: =+AE20*$W$8 -> 48772.11 | X20: =+AF20*$X$8 -> 48772.11 | Y20: 0 | Z20: =SUM(V20:Y20) -> 195088.44 | AA20: 0 | AB20: =+O20-Z20-AA20 -> 5557957.6 | AE20: 4877211 | AF20: 4877211 | AG20: =+O20+P20+S20 -> 6006173.3 | AH20: =IF(AG20*0.05>500000,500000,AG20*0.05) -> 300308.66 | AI20: =+AG20-AH20-V20-W20 -> 5559548.3 | AJ20: =+AI20*$AJ$8 -> 66714579 | AK20: =IF(D20="TK",54000000,(IF(OR(D20="TK1",D20="K"),58500000,(IF(OR(D20="TK2",D20="K1"),63000000,(IF(OR(OR(D20="TK3",D20="TK4"),D20="K2"),67500000,72000000))))))) -> 67500000 | AL20: =IF((+AJ20-AK20)<=0,0,TRUNC((AJ20-AK20)/1000)*1000) -> 0 | AM20: =IF(AL20<=60000000,AL20*5%,IF(AL20<=250000000,3000000+((AL20-60000000)*15%),IF(AL20<=500000000,31500000+((AL20-250000000)*25%),IF(AND(AL20>=500000000,AL20<=5000000000),94000000+((AL20-500000000)*30%),IF(AL20>5000000000,(1444000000+(AL20-5000000000)*35%)))))) -> 0 | AN20: =+AM20/12 -> 0
A21: 12 | B21: NOVA SUGANDI | C21: DRIVER | D21: K | E21: 3201020508760012 | F21: 4494855 | G21: 44.5 | H21: =+F21/173 -> 25981.821 | I21: =+G21*H21 -> 1156191 | J21: 0 | K21: 0 | M21: 108000 | O21: =+F21+I21+J21+K21+M21+N21 -> 5759046 | P21: =+AE21*$P$8 -> 58038.811 | Q21: =+AE21*$Q$8 -> 97544.22 | R21: =+AE21*$R$8 -> 97544.22 | S21: =+AF21*$S$8 -> 195088.44 | T21: =SUM(P21:S21) -> 448215.69 | U21: =+O21+T21 -> 6207261.7 | V21: =+AE21*$V$8 -> 97544.22 | W21: =+AE21*$W$8 -> 48772.11 | X21: =+AF21*$X$8 -> 48772.11 | Y21: 0 | Z21: =SUM(V21:Y21) -> 195088.44 | AA21: 45091 | AB21: =+O21-Z21-AA21 -> 5518866.6 | AE21: 4877211 | AF21: 4877211 | AG21: =+O21+P21+S21 -> 6012173.3 | AH21: =IF(AG21*0.05>500000,500000,AG21*0.05) -> 300608.66 | AI21: =+AG21-AH21-V21-W21 -> 5565248.3 | AJ21: =+AI21*$AJ$8 -> 66782979 | AK21: =IF(D21="TK",54000000,(IF(OR(D21="TK1",D21="K"),58500000,(IF(OR(D21="TK2",D21="K1"),63000000,(IF(OR(OR(D21="TK3",D21="TK4"),D21="K2"),67500000,72000000))))))) -> 58500000 | AL21: =IF((+AJ21-AK21)<=0,0,TRUNC((AJ21-AK21)/1000)*1000) -> 8282000 | AM21: =IF(AL21<=60000000,AL21*5%,IF(AL21<=250000000,3000000+((AL21-60000000)*15%),IF(AL21<=500000000,31500000+((AL21-250000000)*25%),IF(AND(AL21>=500000000,AL21<=5000000000),94000000+((AL21-500000000)*30%),IF(AL21>5000000000,(1444000000+(AL21-5000000000)*35%)))))) -> 414100 | AN21: =+AM21/12 -> 34508.333
A22: 13 | B22: JAMALUDIN | C22: DRIVER | D22: K2 | F22: 4494855 | G22: 91.5 | H22: =+F22/173 -> 25981.821 | I22: =+G22*H22 -> 2377336.6 | J22: 0 | K22: 0 | M22: 132000 | O22: =+F22+I22+J22+K22+M22+N22 -> 7004191.6 | P22: =+AE22*$P$8 -> 58038.811 | Q22: =+AE22*$Q$8 -> 97544.22 | R22: =+AE22*$R$8 -> 97544.22 | S22: =+AF22*$S$8 -> 195088.44 | T22: =SUM(P22:S22) -> 448215.69 | U22: =+O22+T22 -> 7452407.3 | V22: =+AE22*$V$8 -> 97544.22 | W22: =+AE22*$W$8 -> 48772.11 | X22: =+AF22*$X$8 -> 48772.11 | Y22: 0 | Z22: =SUM(V22:Y22) -> 195088.44 | AA22: 36287 | AB22: =+O22-Z22-AA22 -> 6772816.2 | AE22: 4877211 | AF22: 4877211 | AG22: =+O22+P22+S22 -> 7257318.9
A24: SUB TOTAL | F24: =SUM(F10:F23) -> 60462539 | G24: =SUM(G14:G23) -> 483.5 | I24: =SUM(I10:I23) -> 12821732 | J24: =SUM(J10:J23) -> 400000 | K24: =SUM(K10:K23) -> 0 | L24: =SUM(L9:L23) -> 0 | M24: =SUM(M10:M23) -> 1764000 | N24: =SUM(N10:N23) -> 0 | O24: =SUM(O10:O23) -> 75448271 | P24: =SUM(P10:P23) -> 754504.54 | Q24: =SUM(Q10:Q23) -> 1268074.9 | R24: =SUM(R10:R23) -> 1268074.9 | S24: =SUM(S10:S23) -> 2536149.7 | T24: =SUM(T10:T23) -> 5826804 | ... AB24: =SUM(AB10:AB23) -> 72631908 | AG24: =SUM(AG10:AG23) -> 78738925 | AI24: =SUM(AI10:AI23) -> 66151730
P25: =+P24+Q24+R24+V24+W24 -> 5192766.6 | S25: =+S24+X24+Y24 -> 3170187.1 | AB25: =+AB24 -> 72631908 | AI25: =SUM([3]GENERAL!$AA$27:$AA$40) -> 66596371
AE27: =+AE18-T13 -> 4428995.3
Q30: =40+175+2606 -> 2821

Sheet SLIP-GENERAL
B4: SLIP GAJI | L4: SLIP GAJI
B5: No. Urut | C5: : | D5: ='[2]G-STAFF'!A35 -> 1 | L5: No. Urut | M5: : | N5: ='[2]G-STAFF'!A36 -> 2
B6: Periode | C6: : | D6: ='[2]G-STAFF'!A3 -> 01 JANUARI S/D 31 JANUARI 2025 | L6: Periode | M6: : | N6: ='[2]G-STAFF'!A3 -> 01 JANUARI S/D 31 JANUARI 2025
B7: Nama Karyawan | C7: : | D7: ='[2]G-STAFF'!B35 -> DEDE IRAWAN | L7: Nama Karyawan | M7: : | N7: ='[2]G-STAFF'!B36 -> DONI IMAM SAPUTRO
B8: Bagian / Jabatan | C8: : | D8: ='[2]G-STAFF'!H35 -> SECURITY | L8: Bagian / Jabatan | M8: : | N8: ='[2]G-STAFF'!H36 -> SECURITY
B10: PENERIMAAN | L10: PENERIMAAN
B11: GAJI POKOK | H11: =+GENERAL!F10 -> 4877211 | L11: GAJI POKOK | R11: =+GENERAL!F11 -> 4594855
B12: TUNJANGAN JABATAN | H12: =+GENERAL!J10 -> 0 | L12: TUNJANGAN JABATAN | R12: =+GENERAL!J11 -> 0
B13: TUNJANGAN BPJS | H13: =+GENERAL!T10 -> 448215.69 | L13: TUNJANGAN BPJS | R13: =+GENERAL!T11 -> 448215.69
B14: UANG MAKAN | H14: =+GENERAL!M10 -> 180000 | L14: UANG MAKAN | R14: =+GENERAL!M11 -> 180000
B15: LEMBUR WAJIB | D15: ='[2]G-STAFF'!V35 -> 0 | E15: HARI | F15: X | G15: ='[2]G-STAFF'!U35 -> 160464.57 | H15: =G15*D15 -> 0 | L15: LEMBUR WAJIB | N15: ='[2]G-STAFF'!V36 -> 0 | O15: HARI | P15: X | Q15: ='[2]G-STAFF'!U36 -> 117810.33 | R15: =Q15*N15 -> 0
B16: HL/HM/HR | D16: ='[2]G-STAFF'!CH35 -> 0 | E16: JAM | F16: X | G16: ='[2]G-STAFF'!M35 -> 27826.225 | H16: =G16*D16 -> 0 | L16: HL/HM/HR | N16: ='[2]G-STAFF'!CH36 -> 0 | O16: JAM | P16: X | Q16: ='[2]G-STAFF'!M36 -> 20429.538 | R16: =Q16*N16 -> 0
B17: H.BIASA | D17: ='[2]G-STAFF'!CG35 -> 0 | E17: JAM | F17: X | G17: =G16 -> 27826.225 | H17: =G17*D17 -> 0 | L17: H.BIASA | N17: ='[2]G-STAFF'!CG36 -> 0 | O17: JAM | P17: X | Q17: =Q16 -> 20429.538 | R17: =Q17*N17 -> 0
B18: TOTAL | D18: ='[2]G-STAFF'!CI35 -> 0 | H18: =SUM(H11:H17) -> 5505426.7 | L18: TOTAL | N18: ='[2]G-STAFF'!CI36 -> 0 | R18: =SUM(R11:R17) -> 5223070.7
B20: POTONGAN | L20: POTONGAN
B21: PPH 21 | G21: ='[2]G-STAFF'!C35 -> K1 | H21: =+GENERAL!AA10 -> 0 | L21: PPH 21 | Q21: ='[2]G-STAFF'!C36 -> TK | R21: =+GENERAL!AA10 -> 0
B22: BPJS KES 1% | H22: =+GENERAL!X10+GENERAL!Y10 -> 48772.11 | L22: BPJS KES 1% | R22: =+GENERAL!X10+GENERAL!Y10 -> 48772.11
B23: BPJS TK 3% | H23: =+GENERAL!V10+GENERAL!W10 -> 146316.33 | L23: BPJS TK 3% | R23: =+GENERAL!V10+GENERAL!W10 -> 146316.33
B24: BPJS DITANGGUNG PERUSAHAAN | H24: =+H13 -> 448215.69 | L24: BPJS DITANGGUNG PERUSAHAAN | R24: =+R13 -> 448215.69
B25: TOTAL POTONGAN | H25: =SUM(H21:H24) -> 643304.13 | L25: TOTAL POTONGAN | R25: =SUM(R21:R24) -> 643304.13
B26: TOTAL GAJI | H26: =H18-H25 -> 4862122.6 | L26: TOTAL GAJI | R26: =SUM(R18-R25) -> 4579766.6
B27: KAS NON SHIFT | H27: ='[2]Urutan Nm'!H68 -> 10000 | L27: KAS NON SHIFT | R27: ='[2]Urutan Nm'!H69 -> 10000
B29: TOTAL GAJI DITERIMA | H29: =SUM(H26-H27) -> 4852122.6 | L29: TOTAL GAJI DITERIMA | R29: =SUM(R26-R27) -> 4569766.6
B30: DIBUAT | G30: DITERIMA | L30: DIBUAT | Q30: DITERIMA
B33: (__________________) | G33: (________________) | L33: (__________________) | Q33: (________________)
B39: SLIP GAJI | L39: SLIP GAJI
B40: No. Urut | C40: : | D40: ='[2]G-STAFF'!A37 -> 3 | L40: No. Urut | M40: : | N40: ='[2]G-STAFF'!A38 -> 4
B41: Periode | C41: : | D41: ='[2]G-STAFF'!A3 -> 01 JANUARI S/D 31 JANUARI 2025 | L41: Periode | M41: : | N41: ='[2]G-STAFF'!A3 -> 01 JANUARI S/D 31 JANUARI 2025
B42: Nama Karyawan | C42: : | D42: ='[2]G-STAFF'!B37 -> ANDIKA WIJAYA | L42: Nama Karyawan | M42: : | N42: ='[2]G-STAFF'!B38 -> SAMANHUDI
B43: Bagian / Jabatan | C43: : | D43: ='[2]G-STAFF'!H36 -> SECURITY | L43: Bagian / Jabatan | M43: : | N43: ='[2]G-STAFF'!H38 -> SECURITY
B45: PENERIMAAN | L45: PENERIMAAN
B46: GAJI POKOK | H46: =+GENERAL!F12 -> 4594855 | L46: GAJI POKOK | R46: =+GENERAL!F13 -> 4594855
B47: TUNJANGAN JABATAN | H47: =+GENERAL!J12 -> 0 | L47: TUNJANGAN JABATAN | R47: =+GENERAL!J13 -> 0
B48: TUNJANGAN BPJS | H48: =+GENERAL!T12 -> 448215.69 | L48: TUNJANGAN BPJS | R48: =+GENERAL!T13 -> 448215.69
B49: UANG MAKAN | D49: ='[2]G-STAFF'!Z37 -> 31 | E49: H.K | F49: X | G49: 6000 | H49: =+GENERAL!M12 -> 180000 | L49: UANG MAKAN | N49: ='[2]G-STAFF'!Z38 -> 31 | O49: H.K | P49: X | Q49: 6000 | R49: =+GENERAL!M13 -> 180000
B50: LEMBUR WAJIB | D50: ='[2]G-STAFF'!V37 -> 0 | E50: HARI | F50: X | G50: ='[2]G-STAFF'!U37 -> 127552.93 | H50: =G50*D50 -> 0 | L50: LEMBUR WAJIB | N50: ='[2]G-STAFF'!V38 -> 0 | O50: HARI | P50: X | Q50: ='[2]G-STAFF'!U38 -> 141814.67 | R50: =Q50*N50 -> 0
B51: HL/HM/HR | D51: ='[2]G-STAFF'!CH37 -> 0 | E51: JAM | F51: X | G51: ='[2]G-STAFF'!M37 -> 22119.006 | H51: =G51*D51 -> 0 | L51: HL/HM/HR | N51: ='[2]G-STAFF'!CH38 -> 0 | O51: JAM | P51: X | Q51: ='[2]G-STAFF'!M38 -> 24592.139 | R51: =Q51*N51 -> 0
B52: H.BIASA | D52: ='[2]G-STAFF'!CG37 -> 0 | E52: JAM | F52: X | G52: =G51 -> 22119.006 | H52: =G52*D52 -> 0 | L52: H.BIASA | N52: ='[2]G-STAFF'!CG38 -> 0 | O52: JAM | P52: X | Q52: =Q51 -> 24592.139 | R52: =Q52*N52 -> 0
B53: TOTAL | D53: ='[2]G-STAFF'!CI37 -> 0 | H53: =SUM(H46:H52) -> 5223070.7 | L53: TOTAL | N53: ='[2]G-STAFF'!CI38 -> 0 | R53: =SUM(R46:R52) -> 5223070.7
B55: POTONGAN | L55: POTONGAN
...

Sheet PRODUKSI 1
A1: PT INDOBOX UTAMA JAYA
A2: DAFTAR GAJI PRODUKSI 1
A3: PERIODE 01 NOVEMBER S/D 30 NOVEMBER 2025
A5: NO | B5: NAMA | C5: BAGIAN | D5: STS | E5: NIK | F5: HARI KERJA | G5: GAJI POKOK | H5: GAJI POKOK | I5: TUNJANGAN | L5: JAM OT | R5: TOTAL LEMBUR | S5: UANG MAKAN | T5: BONUS | U5: THR | V5: TOTAL GAJI | W5: BPJS DITANGGUNG PERUSAHAAN | AA5: BPJS PER- USAHAAN | AB5: GAJI BRUTO | AC5: BPJS DITANGGUNG KARYAWAN | AG5: POTONGAN | AI5: TOTAL GAJI SETELAH BPJS DAN PAJAK | AL5: BPJS TK | AM5: JKN | AN5: GAJI BRUTO | AO5: BIAYA JABATAN | AP5: GAJI NETTO | AQ5: GAJI SETAHUN | AR5: PTKP | AS5: PKP | AT5: PPH 21 SETAHUN | AU5: PPH 21 SEBULAN
I6: UANG JABATAN | J6: PRESTASI | K6: INSENTIF | W6: JKK JKM | X6: JHT | Y6: JP | Z6: BPJS KES | AC6: JHT | AD6: JP | AE6: BPJS KES | AF6: TAMBAHAN | AG6: BPJS | AH6: PPh 21
W7: 0.0119 | X7: 0.02 | Y7: 0.02 | Z7: 0.04 | AC7: 0.02 | AD7: 0.01 | AE7: 0.01 | AF7: 0.01 | AG7: TK + JKN | AO7: 0.05 | AQ7: 12
A9: 1 | B9: ENANG BIN LAMIN | C9: MOUNTING | D9: K2 | E9: 3201022904800009 | F9: 30 | G9: 145452 | H9: 4594855 | I9: 100000 | J9: 100000 | O9: 0 | P9: 26559.855 | Q9: =+O9*P9 -> 0 | R9: =+N9+Q9 -> 0 | S9: 100000 | U9: 0 | V9: =+H9+I9+J9+K9+R9+S9+U9 -> 4894855 | W9: =+AL9*$W$7 -> 58038.811 | X9: =+AL9*$X$7 -> 97544.22 | Y9: =+AL9*$Y$7 -> 97544.22 | Z9: =+AM9*$Z$7 -> 195088.44 | AA9: =SUM(W9:Z9) -> 448215.69 | AB9: =+V9+AA9 -> 5343070.7 | AC9: =+AL9*$AC$7 -> 97544.22 | AD9: =+AL9*$AD$7 -> 48772.11 | AE9: =+AM9*$AE$7 -> 48772.11 | AF9: 0 | AG9: =SUM(AC9:AF9) -> 195088.44 | AH9: 0 | AI9: =+V9-AG9-AH9 -> 4699766.6 | AL9: 4877211 | AM9: 4877211 | AN9: =+V9+W9+Z9 -> 5147982.3 | AO9: =IF(AN9*0.05>500000,500000,AN9*0.05) -> 257399.11 | AP9: =+AN9-AO9-AC9-AD9 -> 4744266.8 | AQ9: =+AP9*$AQ$7 -> 56931202 | AR9: =IF(D9="TK",54000000,(IF(OR(D9="TK1",D9="K"),58500000,(IF(OR(D9="TK2",D9="K1"),63000000,(IF(OR(OR(D9="TK3",D9="TK4"),D9="K2"),67500000,72000000))))))) -> 67500000 | AS9: =IF((+AQ9-AR9)<=0,0,TRUNC((AQ9-AR9)/1000)*1000) -> 0 | AT9: =IF(AS9<=60000000,AS9*5%,IF(AS9<=250000000,3000000+((AS9-60000000)*15%),IF(AS9<=500000000,31500000+((AS9-250000000)*25%),IF(AND(AS9>=500000000,AS9<=5000000000),94000000+((AS9-500000000)*30%),IF(AS9>5000000000,(1444000000+(AS9-5000000000)*35%)))))) -> 0 | AU9: =+AT9/12 -> 0
A10: 2 | B10: HERMAN | C10: DELIVERY | D10: K2 | E10: 3201020304740014 | F10: 19 | G10: 145452 | H10: 4594855 | I10: 0 | J10: 0 | O10: 36 | P10: 26559.855 | Q10: =+O10*P10 -> 956154.8 | R10: =+N10+Q10 -> 956154.8 | S10: 60000 | U10: 0 | V10: =+H10+I10+J10+K10+R10+S10+U10 -> 5611009.8 | W10: =+AL10*$W$7 -> 58038.811 | X10: =+AL10*$X$7 -> 97544.22 | Y10: =+AL10*$Y$7 -> 97544.22 | Z10: =+AM10*$Z$7 -> 195088.44 | AA10: =SUM(W10:Z10) -> 448215.69 | AB10: =+V10+AA10 -> 6059225.5 | AC10: =+AL10*$AC$7 -> 97544.22 | AD10: =+AL10*$AD$7 -> 48772.11 | AE10: =+AM10*$AE$7 -> 48772.11 | AG10: =SUM(AC10:AF10) -> 195088.44 | AH10: 0 | AI10: =+V10-AG10-AH10 -> 5415921.4 | AL10: 4877211 | AM10: 4877211 | AN10: =+V10+W10+Z10 -> 5864137 | AO10: =IF(AN10*0.05>500000,500000,AN10*0.05) -> 293206.85 | AP10: =+AN10-AO10-AC10-AD10 -> 5424613.9 | AQ10: =+AP10*$AQ$7 -> 65095366 | AR10: =IF(D10="TK",54000000,(IF(OR(D10="TK1",D10="K"),58500000,(IF(OR(D10="TK2",D10="K1"),63000000,(IF(OR(OR(D10="TK3",D10="TK4"),D10="K2"),67500000,72000000))))))) -> 67500000 | AS10: =IF((+AQ10-AR10)<=0,0,TRUNC((AQ10-AR10)/1000)*1000) -> 0 | AT10: =IF(AS10<=60000000,AS10*5%,IF(AS10<=250000000,3000000+((AS10-60000000)*15%),IF(AS10<=500000000,31500000+((AS10-250000000)*25%),IF(AND(AS10>=500000000,AS10<=5000000000),94000000+((AS10-500000000)*30%),IF(AS10>5000000000,(1444000000+(AS10-5000000000)*35%)))))) -> 0 | AU10: =+AT10/12 -> 0
